<?xml version="1.0" ?>
<robot name="bot" xmlns:xacro="http://www.ros.org/wiki/xacro">

<xacro:include filename="$(find bot_description)/urdf/materials.xacro" />
<xacro:include filename="$(find bot_description)/urdf/bot.trans" />
<xacro:include filename="$(find bot_description)/urdf/bot.gazebo" />
<link name="base_link">
  <inertial>
    <origin xyz="0.0020394017926573475 -9.274503162711054e-08 0.037865804686589045" rpy="0 0 0"/>
    <mass value="6.594639811774716"/>
    <inertia ixx="0.012007" iyy="0.018602" izz="0.02919" ixy="0.0" iyz="-0.0" ixz="-0.000227"/>
  </inertial>
  <visual>
    <origin xyz="0 0 0" rpy="0 0 0"/>
    <geometry>
      <mesh filename="package://bot_description/meshes/base_link.stl" scale="0.001 0.001 0.001"/>
    </geometry>
    <material name="silver"/>
  </visual>
  <collision>
    <origin xyz="0 0 0" rpy="0 0 0"/>
    <geometry>
      <mesh filename="package://bot_description/meshes/base_link.stl" scale="0.001 0.001 0.001"/>
    </geometry>
  </collision>
</link>

<link name="left_wheel_1">
  <inertial>
    <origin xyz="-9.56179579958416e-15 -0.0050000000000000044 -1.3877787807814457e-17" rpy="0 0 0"/>
    <mass value="0.33749938763215337"/>
    <inertia ixx="0.000123" iyy="0.000239" izz="0.000123" ixy="0.0" iyz="0.0" ixz="-0.0"/>
  </inertial>
  <visual>
    <origin xyz="0.075 -0.085 -0.0375" rpy="0 0 0"/>
    <geometry>
      <mesh filename="package://bot_description/meshes/left_wheel_1.stl" scale="0.001 0.001 0.001"/>
    </geometry>
    <material name="silver"/>
  </visual>
  <collision>
    <origin xyz="0.075 -0.085 -0.0375" rpy="0 0 0"/>
    <geometry>
      <mesh filename="package://bot_description/meshes/left_wheel_1.stl" scale="0.001 0.001 0.001"/>
    </geometry>
  </collision>
</link>

<link name="right_wheel_1">
  <inertial>
    <origin xyz="-9.56179579958416e-15 0.0049999999999999906 0.0" rpy="0 0 0"/>
    <mass value="0.33749938763215337"/>
    <inertia ixx="0.000123" iyy="0.000239" izz="0.000123" ixy="0.0" iyz="-0.0" ixz="-0.0"/>
  </inertial>
  <visual>
    <origin xyz="0.075 0.085 -0.0375" rpy="0 0 0"/>
    <geometry>
      <mesh filename="package://bot_description/meshes/right_wheel_1.stl" scale="0.001 0.001 0.001"/>
    </geometry>
    <material name="silver"/>
  </visual>
  <collision>
    <origin xyz="0.075 0.085 -0.0375" rpy="0 0 0"/>
    <geometry>
      <mesh filename="package://bot_description/meshes/right_wheel_1.stl" scale="0.001 0.001 0.001"/>
    </geometry>
  </collision>
</link>

<link name="castor_1">
  <inertial>
    <origin xyz="-2.7755575615628914e-17 -5.911529352152055e-18 -0.008348053398638122" rpy="0 0 0"/>
    <mass value="0.18870786706611672"/>
    <inertia ixx="2.5e-05" iyy="2.5e-05" izz="3.9e-05" ixy="-0.0" iyz="-0.0" ixz="-0.0"/>
  </inertial>
  <visual>
    <origin xyz="-0.07 -0.0 -0.0215" rpy="0 0 0"/>
    <geometry>
      <mesh filename="package://bot_description/meshes/castor_1.stl" scale="0.001 0.001 0.001"/>
    </geometry>
    <material name="silver"/>
  </visual>
  <collision>
    <origin xyz="-0.07 -0.0 -0.0215" rpy="0 0 0"/>
    <geometry>
      <mesh filename="package://bot_description/meshes/castor_1.stl" scale="0.001 0.001 0.001"/>
    </geometry>
  </collision>
</link>

<link name="lidar_1">
  <inertial>
    <origin xyz="0.0 0.0 0.0050000000000000044" rpy="0 0 0"/>
    <mass value="0.12484885554906686"/>
    <inertia ixx="1.7e-05" iyy="1.7e-05" izz="3.2e-05" ixy="-0.0" iyz="0.0" ixz="0.0"/>
  </inertial>
  <visual>
    <origin xyz="-0.025 -0.0 -0.0775" rpy="0 0 0"/>
    <geometry>
      <mesh filename="package://bot_description/meshes/lidar_1.stl" scale="0.001 0.001 0.001"/>
    </geometry>
    <material name="silver"/>
  </visual>
  <collision>
    <origin xyz="-0.025 -0.0 -0.0775" rpy="0 0 0"/>
    <geometry>
      <mesh filename="package://bot_description/meshes/lidar_1.stl" scale="0.001 0.001 0.001"/>
    </geometry>
  </collision>
</link>

<joint name="Revolute1" type="continuous">
  <origin xyz="-0.075 0.085 0.0375" rpy="0 0 0"/>
  <parent link="base_link"/>
  <child link="left_wheel_1"/>
  <axis xyz="0.0 1.0 0.0"/>
</joint>

<joint name="Revolute2" type="continuous">
  <origin xyz="-0.075 -0.085 0.0375" rpy="0 0 0"/>
  <parent link="base_link"/>
  <child link="right_wheel_1"/>
  <axis xyz="0.0 1.0 0.0"/>
</joint>

<joint name="Rigid3" type="fixed">
  <origin xyz="0.07 0.0 0.0215" rpy="0 0 0"/>
  <parent link="base_link"/>
  <child link="castor_1"/>
</joint>

<joint name="Rigid4" type="fixed">
  <origin xyz="0.025 0.0 0.0775" rpy="0 0 0"/>
  <parent link="base_link"/>
  <child link="lidar_1"/>
</joint>

</robot>
